<?xml version="1.0" encoding="utf-8" ?>
<!-- This URDF was automatically created by SolidWorks to URDF Exporter! Originally created by Stephen Brawner (brawner@gmail.com) 
     Commit Version: 1.5.1-0-g916b5db  Build Version: 1.5.7152.31018
     For more information, please see http://wiki.ros.org/sw_urdf_exporter -->
<robot name="robot">
    <link name="base_link">
        
<inertial>
            <origin xyz="-1.1972E-34 0.02164 7.822E-19" rpy="0 0 0" />
            <mass value="1.8374" />
            <inertia ixx="0.0025933" ixy="-5.3289E-36" ixz="-8.8442E-36" iyy="0.0043402" iyz="-3.3309E-20" izz="0.0025933" />
        </inertial>

        <visual>
            <origin xyz="0 0 0" rpy="0 0 0" />
            <geometry>
                <mesh filename="package://robot/meshes/base_link.STL" />
            </geometry>
            <material name="">
                <color rgba="0.89804 0.91765 0.92941 1" />
            </material>
        </visual>
        <collision>
            <origin xyz="0 0 0" rpy="0 0 0" />
            <geometry>
                <mesh filename="package://robot/meshes/base_link.STL" />
            </geometry>
        </collision>
    </link>
    <link name="link1">
        
<inertial>
            <origin xyz="0.00061423 0.1001 -7.8675E-09" rpy="0 0 0" />
            <mass value="2.7255" />
            <inertia ixx="0.010091" ixy="-0.00012814" ixz="-9.1718E-10" iyy="0.0022058" iyz="-1.5836E-09" izz="0.010151" />
        </inertial>

        <visual>
            <origin xyz="0 0 0" rpy="0 0 0" />
            <geometry>
                <mesh filename="package://robot/meshes/link1.STL" />
            </geometry>
            <material name="">
                <color rgba="0.89804 0.91765 0.92941 1" />
            </material>
        </visual>
        <collision>
            <origin xyz="0 0 0" rpy="0 0 0" />
            <geometry>
                <mesh filename="package://robot/meshes/link1.STL" />
            </geometry>
        </collision>
    </link>
    <joint name="joint1" type="continuous">
        <origin xyz="0 0 0.06" rpy="1.5708 0 0.21073" />
        <parent link="base_link" />
        <child link="link1" />
        <axis xyz="0 1 0" />
    </joint>
    <link name="link2">
        
<inertial>
            <origin xyz="-0.040667 -0.074901 -7.6586E-09" rpy="0 0 0" />
            <mass value="2.7255" />
            <inertia ixx="0.010091" ixy="-0.00012815" ixz="1.276E-10" iyy="0.0022058" iyz="6.9045E-10" izz="0.010151" />
        </inertial>

        <visual>
            <origin xyz="0 0 0" rpy="0 0 0" />
            <geometry>
                <mesh filename="package://robot/meshes/link2.STL" />
            </geometry>
            <material name="">
                <color rgba="0.89804 0.91765 0.92941 1" />
            </material>
        </visual>
        <collision>
            <origin xyz="0 0 0" rpy="0 0 0" />
            <geometry>
                <mesh filename="package://robot/meshes/link2.STL" />
            </geometry>
        </collision>
    </link>
    <joint name="joint2" type="continuous">
        <origin xyz="0.048719 0.175 0" rpy="0.18585 0 -3.1416" />
        <parent link="link1" />
        <child link="link2" />
        <axis xyz="1 0 0" />
    </joint>
    <link name="link3">
        
<inertial>
            <origin xyz="-0.00037429 0.13125 0.033665" rpy="0 0 0" />
            <mass value="4.47" />
            <inertia ixx="0.031917" ixy="0.00010051" ixz="0.00015564" iyy="0.013008" iyz="-0.0090516" izz="0.022571" />
        </inertial>

        <visual>
            <origin xyz="0 0 0" rpy="0 0 0" />
            <geometry>
                <mesh filename="package://robot/meshes/link3.STL" />
            </geometry>
            <material name="">
                <color rgba="0.89804 0.91765 0.92941 1" />
            </material>
        </visual>
        <collision>
            <origin xyz="0 0 0" rpy="0 0 0" />
            <geometry>
                <mesh filename="package://robot/meshes/link3.STL" />
            </geometry>
        </collision>
    </link>
    <joint name="joint3" type="continuous">
        <origin xyz="-0.041281 -0.1837 0" rpy="0 -0.27626 -3.1416" />
        <parent link="link2" />
        <child link="link3" />
        <axis xyz="0 1 0" />
    </joint>
    <link name="link4">
        
<inertial>
            <origin xyz="-0.058475 0.05 0.00081343" rpy="0 0 0" />
            <mass value="2.058" />
            <inertia ixx="0.004593" ixy="8.6485E-05" ixz="1.3447E-06" iyy="0.0016966" iyz="-8.6472E-05" izz="0.0045929" />
        </inertial>

        <visual>
            <origin xyz="0 0 0" rpy="0 0 0" />
            <geometry>
                <mesh filename="package://robot/meshes/link4.STL" />
            </geometry>
            <material name="">
                <color rgba="0.89804 0.91765 0.92941 1" />
            </material>
        </visual>
        <collision>
            <origin xyz="0 0 0" rpy="0 0 0" />
            <geometry>
                <mesh filename="package://robot/meshes/link4.STL" />
            </geometry>
        </collision>
    </link>
    <joint name="joint4" type="continuous">
        <origin xyz="-0.030712 0.1913 0.125" rpy="1.6143 0 0" />
        <parent link="link3" />
        <child link="link4" />
        <axis xyz="1 0 0" />
    </joint>
    <link name="link5">
        
<inertial>
            <origin xyz="0.0035832 0.10274 -1.2028E-07" rpy="0 0 0" />
            <mass value="1.1725" />
            <inertia ixx="0.0042609" ixy="-0.00028758" ixz="8.1052E-09" iyy="0.00047495" iyz="2.0701E-08" izz="0.0043661" />
        </inertial>

        <visual>
            <origin xyz="0 0 0" rpy="0 0 0" />
            <geometry>
                <mesh filename="package://robot/meshes/link5.STL" />
            </geometry>
            <material name="">
                <color rgba="0.89804 0.91765 0.92941 1" />
            </material>
        </visual>
        <collision>
            <origin xyz="0 0 0" rpy="0 0 0" />
            <geometry>
                <mesh filename="package://robot/meshes/link5.STL" />
            </geometry>
        </collision>
    </link>
    <joint name="joint5" type="continuous">
        <origin xyz="-0.059288 0.1 0.049181" rpy="1.5708 0 3.0915" />
        <parent link="link4" />
        <child link="link5" />
        <axis xyz="0 1 0" />
    </joint>
    <link name="link6">
        
<inertial>
            <origin xyz="-0.043141 -0.019673 -9.3691E-08" rpy="0 0 0" />
            <mass value="0.62459" />
            <inertia ixx="0.00055035" ixy="-8.4209E-05" ixz="2.3334E-09" iyy="0.00028736" iyz="4.4142E-09" izz="0.00064236" />
        </inertial>

        <visual>
            <origin xyz="0 0 0" rpy="0 0 0" />
            <geometry>
                <mesh filename="package://robot/meshes/link6.STL" />
            </geometry>
            <material name="">
                <color rgba="0.89804 0.91765 0.92941 1" />
            </material>
        </visual>
        <collision>
            <origin xyz="0 0 0" rpy="0 0 0" />
            <geometry>
                <mesh filename="package://robot/meshes/link6.STL" />
            </geometry>
        </collision>
    </link>
    <joint name="joint6" type="continuous">
        <origin xyz="0.040133 0.17082 0" rpy="-0.71838 0 3.1416" />
        <parent link="link5" />
        <child link="link6" />
        <axis xyz="1 0 0" />
    </joint>
    <link name="link7">
        
<inertial>
            <origin xyz="0 0.00095811 0" rpy="0 0 0" />
            <mass value="0.0084823" />
            <inertia ixx="2.8274E-07" ixy="4.6322E-23" ixz="-1.9852E-23" iyy="4.2412E-07" iyz="-2.647E-23" izz="2.8274E-07" />
        </inertial>

        <visual>
            <origin xyz="0 0 0" rpy="0 0 0" />
            <geometry>
                <mesh filename="package://robot/meshes/link7.STL" />
            </geometry>
            <material name="">
                <color rgba="0.89804 0.91765 0.92941 1" />
            </material>
        </visual>
        <collision>
            <origin xyz="0 0 0" rpy="0 0 0" />
            <geometry>
                <mesh filename="package://robot/meshes/link7.STL" />
            </geometry>
        </collision>
    </link>
    <joint name="joint7" type="continuous">
        <origin xyz="-0.049867 -0.079042 0" rpy="0 0.61703 -3.1416" />
        <parent link="link6" />
        <child link="link7" />
        <axis xyz="0 1 0" />
    </joint>
    
<transmission name="trans_joint1">
        <type>transmission_interface/SimpleTransmission</type>
        <joint name="joint1">
            <hardwareInterface>hardware_interface/EffortJointInterface</hardwareInterface>
        </joint>
        <actuator name="joint1_motor">
            <hardwareInterface>hardware_interface/EffortJointInterface</hardwareInterface>
            <mechanicalReduction>1</mechanicalReduction>
        </actuator>
    </transmission>
    <transmission name="trans_joint2">
        <type>transmission_interface/SimpleTransmission</type>
        <joint name="joint2">
            <hardwareInterface>hardware_interface/EffortJointInterface</hardwareInterface>
        </joint>
        <actuator name="joint2_motor">
            <hardwareInterface>hardware_interface/EffortJointInterface</hardwareInterface>
            <mechanicalReduction>1</mechanicalReduction>
        </actuator>
    </transmission>
    <transmission name="trans_joint3">
        <type>transmission_interface/SimpleTransmission</type>
        <joint name="joint3">
            <hardwareInterface>hardware_interface/EffortJointInterface</hardwareInterface>
        </joint>
        <actuator name="joint3_motor">
            <hardwareInterface>hardware_interface/EffortJointInterface</hardwareInterface>
            <mechanicalReduction>1</mechanicalReduction>
        </actuator>
    </transmission>
    <transmission name="trans_joint4">
        <type>transmission_interface/SimpleTransmission</type>
        <joint name="joint4">
            <hardwareInterface>hardware_interface/EffortJointInterface</hardwareInterface>
        </joint>
        <actuator name="joint4_motor">
            <hardwareInterface>hardware_interface/EffortJointInterface</hardwareInterface>
            <mechanicalReduction>1</mechanicalReduction>
        </actuator>
    </transmission>
    <transmission name="trans_joint5">
        <type>transmission_interface/SimpleTransmission</type>
        <joint name="joint5">
            <hardwareInterface>hardware_interface/EffortJointInterface</hardwareInterface>
        </joint>
        <actuator name="joint5_motor">
            <hardwareInterface>hardware_interface/EffortJointInterface</hardwareInterface>
            <mechanicalReduction>1</mechanicalReduction>
        </actuator>
    </transmission>
    <transmission name="trans_joint6">
        <type>transmission_interface/SimpleTransmission</type>
        <joint name="joint6">
            <hardwareInterface>hardware_interface/EffortJointInterface</hardwareInterface>
        </joint>
        <actuator name="joint6_motor">
            <hardwareInterface>hardware_interface/EffortJointInterface</hardwareInterface>
            <mechanicalReduction>1</mechanicalReduction>
        </actuator>
    </transmission>
    <transmission name="trans_joint7">
        <type>transmission_interface/SimpleTransmission</type>
        <joint name="joint7">
            <hardwareInterface>hardware_interface/EffortJointInterface</hardwareInterface>
        </joint>
        <actuator name="joint7_motor">
            <hardwareInterface>hardware_interface/EffortJointInterface</hardwareInterface>
            <mechanicalReduction>1</mechanicalReduction>
        </actuator>
    </transmission>
    <gazebo>
        <plugin name="gazebo_ros_control" filename="libgazebo_ros_control.so">
            <robotNamespace>/</robotNamespace>
        </plugin>
    </gazebo>
</robot>